Traceback (most recent call last):
  File "/software/Anaconda3-2018.12-el7-x86_64/envs/tf-gpu-1.13.1/lib/python3.7/site-packages/tensorflow/python/pywrap_tensorflow.py", line 58, in <module>
    from tensorflow.python.pywrap_tensorflow_internal import *
  File "/software/Anaconda3-2018.12-el7-x86_64/envs/tf-gpu-1.13.1/lib/python3.7/site-packages/tensorflow/python/pywrap_tensorflow_internal.py", line 28, in <module>
    _pywrap_tensorflow_internal = swig_import_helper()
  File "/software/Anaconda3-2018.12-el7-x86_64/envs/tf-gpu-1.13.1/lib/python3.7/site-packages/tensorflow/python/pywrap_tensorflow_internal.py", line 24, in swig_import_helper
    _mod = imp.load_module('_pywrap_tensorflow_internal', fp, pathname, description)
  File "/software/Anaconda3-2018.12-el7-x86_64/envs/tf-gpu-1.13.1/lib/python3.7/imp.py", line 242, in load_module
    return load_dynamic(name, filename, file)
  File "/software/Anaconda3-2018.12-el7-x86_64/envs/tf-gpu-1.13.1/lib/python3.7/imp.py", line 342, in load_dynamic
    return _load(spec)
ImportError: libcuda.so.1: cannot open shared object file: No such file or directory

During handling of the above exception, another exception occurred:

Traceback (most recent call last):
  File "artifice.py", line 15, in <module>
    import tensorflow as tf
  File "/software/Anaconda3-2018.12-el7-x86_64/envs/tf-gpu-1.13.1/lib/python3.7/site-packages/tensorflow/__init__.py", line 24, in <module>
    from tensorflow.python import pywrap_tensorflow  # pylint: disable=unused-import
  File "/software/Anaconda3-2018.12-el7-x86_64/envs/tf-gpu-1.13.1/lib/python3.7/site-packages/tensorflow/python/__init__.py", line 49, in <module>
    from tensorflow.python import pywrap_tensorflow
  File "/software/Anaconda3-2018.12-el7-x86_64/envs/tf-gpu-1.13.1/lib/python3.7/site-packages/tensorflow/python/pywrap_tensorflow.py", line 74, in <module>
    raise ImportError(msg)
ImportError: Traceback (most recent call last):
  File "/software/Anaconda3-2018.12-el7-x86_64/envs/tf-gpu-1.13.1/lib/python3.7/site-packages/tensorflow/python/pywrap_tensorflow.py", line 58, in <module>
    from tensorflow.python.pywrap_tensorflow_internal import *
  File "/software/Anaconda3-2018.12-el7-x86_64/envs/tf-gpu-1.13.1/lib/python3.7/site-packages/tensorflow/python/pywrap_tensorflow_internal.py", line 28, in <module>
    _pywrap_tensorflow_internal = swig_import_helper()
  File "/software/Anaconda3-2018.12-el7-x86_64/envs/tf-gpu-1.13.1/lib/python3.7/site-packages/tensorflow/python/pywrap_tensorflow_internal.py", line 24, in swig_import_helper
    _mod = imp.load_module('_pywrap_tensorflow_internal', fp, pathname, description)
  File "/software/Anaconda3-2018.12-el7-x86_64/envs/tf-gpu-1.13.1/lib/python3.7/imp.py", line 242, in load_module
    return load_dynamic(name, filename, file)
  File "/software/Anaconda3-2018.12-el7-x86_64/envs/tf-gpu-1.13.1/lib/python3.7/imp.py", line 342, in load_dynamic
    return _load(spec)
ImportError: libcuda.so.1: cannot open shared object file: No such file or directory


Failed to load the native TensorFlow runtime.

See https://www.tensorflow.org/install/errors

for some common reasons and solutions.  Include the entire stack trace
above this error message when asking for help.
